from fastapi import HTTPException, Response
from app.common.database.supabase import supabase
supabase_db = supabase
class AuthRepository:
    @staticmethod
    def insert_user_data(user_data: dict):
        """
        H√†m l∆∞u th√¥ng tin ng∆∞·ªùi d√πng v√†o b·∫£ng users
        """
        try:
            # G·ª≠i y√™u c·∫ßu insert d·ªØ li·ªáu v√†o Supabase
           supabase_db.table("users").insert(user_data).execute()
        except Exception as e:
            raise Exception(f"Error saving user data: {str(e)}")
        
    @staticmethod
    def upsert_oauth_user_data(user_data: dict):
        """
        L∆∞u ho·∫∑c c·∫≠p nh·∫≠t th√¥ng tin ng∆∞·ªùi d√πng t·ª´ Google / Facebook
        """
        try:
            response = supabase_db.table("users") \
                .upsert(user_data, on_conflict="userId") \
                .execute()
            print("‚úÖ User data upserted:", response)
        except Exception as e:
            print("üö® Error saving user data:", str(e))
            raise HTTPException(status_code=500, detail="Error saving user data")